2021-01-19 13:56:37,451 INFO: Microblog startup [in /Users/rmj/github/microblog/app/__init__.py:58]
2021-01-19 14:08:37,545 INFO: Microblog startup [in /Users/rmj/github/microblog/app/__init__.py:58]
2021-01-19 14:09:16,046 ERROR: Exception on /explore [GET] [in /Library/Frameworks/Python.framework/Versions/3.7/lib/python3.7/site-packages/flask/app.py:1892]
Traceback (most recent call last):
  File "/Library/Frameworks/Python.framework/Versions/3.7/lib/python3.7/site-packages/sqlalchemy/sql/elements.py", line 747, in __getattr__
    return getattr(self.comparator, key)
AttributeError: 'Comparator' object has no attribute 'dec'

The above exception was the direct cause of the following exception:

Traceback (most recent call last):
  File "/Library/Frameworks/Python.framework/Versions/3.7/lib/python3.7/site-packages/sqlalchemy/orm/attributes.py", line 236, in __getattr__
    return getattr(self.comparator, key)
  File "/Library/Frameworks/Python.framework/Versions/3.7/lib/python3.7/site-packages/sqlalchemy/util/langhelpers.py", line 987, in __getattr__
    return self._fallback_getattr(key)
  File "/Library/Frameworks/Python.framework/Versions/3.7/lib/python3.7/site-packages/sqlalchemy/orm/properties.py", line 364, in _fallback_getattr
    return getattr(self.__clause_element__(), key)
  File "/Library/Frameworks/Python.framework/Versions/3.7/lib/python3.7/site-packages/sqlalchemy/sql/elements.py", line 758, in __getattr__
    replace_context=err,
  File "/Library/Frameworks/Python.framework/Versions/3.7/lib/python3.7/site-packages/sqlalchemy/util/compat.py", line 182, in raise_
    raise exception
AttributeError: Neither 'AnnotatedColumn' object nor 'Comparator' object has an attribute 'dec'

The above exception was the direct cause of the following exception:

Traceback (most recent call last):
  File "/Library/Frameworks/Python.framework/Versions/3.7/lib/python3.7/site-packages/flask/app.py", line 2447, in wsgi_app
    response = self.full_dispatch_request()
  File "/Library/Frameworks/Python.framework/Versions/3.7/lib/python3.7/site-packages/flask/app.py", line 1952, in full_dispatch_request
    rv = self.handle_user_exception(e)
  File "/Library/Frameworks/Python.framework/Versions/3.7/lib/python3.7/site-packages/flask/app.py", line 1821, in handle_user_exception
    reraise(exc_type, exc_value, tb)
  File "/Library/Frameworks/Python.framework/Versions/3.7/lib/python3.7/site-packages/flask/_compat.py", line 39, in reraise
    raise value
  File "/Library/Frameworks/Python.framework/Versions/3.7/lib/python3.7/site-packages/flask/app.py", line 1950, in full_dispatch_request
    rv = self.dispatch_request()
  File "/Library/Frameworks/Python.framework/Versions/3.7/lib/python3.7/site-packages/flask/app.py", line 1936, in dispatch_request
    return self.view_functions[rule.endpoint](**req.view_args)
  File "/Library/Frameworks/Python.framework/Versions/3.7/lib/python3.7/site-packages/flask_login/utils.py", line 272, in decorated_view
    return func(*args, **kwargs)
  File "/Users/rmj/github/microblog/app/routes.py", line 176, in explore
    posts = Post.query.order_by(Post.timestamp.dec()).all()
  File "/Library/Frameworks/Python.framework/Versions/3.7/lib/python3.7/site-packages/sqlalchemy/orm/attributes.py", line 249, in __getattr__
    replace_context=err,
  File "/Library/Frameworks/Python.framework/Versions/3.7/lib/python3.7/site-packages/sqlalchemy/util/compat.py", line 182, in raise_
    raise exception
AttributeError: Neither 'InstrumentedAttribute' object nor 'Comparator' object associated with Post.timestamp has an attribute 'dec'
2021-01-19 14:10:36,077 INFO: Microblog startup [in /Users/rmj/github/microblog/app/__init__.py:58]
2021-01-19 14:18:01,843 INFO: Microblog startup [in /Users/rmj/github/microblog/app/__init__.py:58]
2021-01-19 14:20:59,430 INFO: Microblog startup [in /Users/rmj/github/microblog/app/__init__.py:58]
2021-01-19 14:21:00,646 ERROR: Exception on /explore [GET] [in /Library/Frameworks/Python.framework/Versions/3.7/lib/python3.7/site-packages/flask/app.py:1892]
Traceback (most recent call last):
  File "/Library/Frameworks/Python.framework/Versions/3.7/lib/python3.7/site-packages/flask/app.py", line 2447, in wsgi_app
    response = self.full_dispatch_request()
  File "/Library/Frameworks/Python.framework/Versions/3.7/lib/python3.7/site-packages/flask/app.py", line 1952, in full_dispatch_request
    rv = self.handle_user_exception(e)
  File "/Library/Frameworks/Python.framework/Versions/3.7/lib/python3.7/site-packages/flask/app.py", line 1821, in handle_user_exception
    reraise(exc_type, exc_value, tb)
  File "/Library/Frameworks/Python.framework/Versions/3.7/lib/python3.7/site-packages/flask/_compat.py", line 39, in reraise
    raise value
  File "/Library/Frameworks/Python.framework/Versions/3.7/lib/python3.7/site-packages/flask/app.py", line 1950, in full_dispatch_request
    rv = self.dispatch_request()
  File "/Library/Frameworks/Python.framework/Versions/3.7/lib/python3.7/site-packages/flask/app.py", line 1936, in dispatch_request
    return self.view_functions[rule.endpoint](**req.view_args)
  File "/Library/Frameworks/Python.framework/Versions/3.7/lib/python3.7/site-packages/flask_login/utils.py", line 272, in decorated_view
    return func(*args, **kwargs)
  File "/Users/rmj/github/microblog/app/routes.py", line 180, in explore
    page, app.config('POSTS_PER_PAGE'), False)
TypeError: 'Config' object is not callable
2021-01-19 14:21:03,532 ERROR: Exception on /explore [GET] [in /Library/Frameworks/Python.framework/Versions/3.7/lib/python3.7/site-packages/flask/app.py:1892]
Traceback (most recent call last):
  File "/Library/Frameworks/Python.framework/Versions/3.7/lib/python3.7/site-packages/flask/app.py", line 2447, in wsgi_app
    response = self.full_dispatch_request()
  File "/Library/Frameworks/Python.framework/Versions/3.7/lib/python3.7/site-packages/flask/app.py", line 1952, in full_dispatch_request
    rv = self.handle_user_exception(e)
  File "/Library/Frameworks/Python.framework/Versions/3.7/lib/python3.7/site-packages/flask/app.py", line 1821, in handle_user_exception
    reraise(exc_type, exc_value, tb)
  File "/Library/Frameworks/Python.framework/Versions/3.7/lib/python3.7/site-packages/flask/_compat.py", line 39, in reraise
    raise value
  File "/Library/Frameworks/Python.framework/Versions/3.7/lib/python3.7/site-packages/flask/app.py", line 1950, in full_dispatch_request
    rv = self.dispatch_request()
  File "/Library/Frameworks/Python.framework/Versions/3.7/lib/python3.7/site-packages/flask/app.py", line 1936, in dispatch_request
    return self.view_functions[rule.endpoint](**req.view_args)
  File "/Library/Frameworks/Python.framework/Versions/3.7/lib/python3.7/site-packages/flask_login/utils.py", line 272, in decorated_view
    return func(*args, **kwargs)
  File "/Users/rmj/github/microblog/app/routes.py", line 180, in explore
    page, app.config('POSTS_PER_PAGE'), False)
TypeError: 'Config' object is not callable
2021-01-19 14:21:05,493 ERROR: Exception on /explore [GET] [in /Library/Frameworks/Python.framework/Versions/3.7/lib/python3.7/site-packages/flask/app.py:1892]
Traceback (most recent call last):
  File "/Library/Frameworks/Python.framework/Versions/3.7/lib/python3.7/site-packages/flask/app.py", line 2447, in wsgi_app
    response = self.full_dispatch_request()
  File "/Library/Frameworks/Python.framework/Versions/3.7/lib/python3.7/site-packages/flask/app.py", line 1952, in full_dispatch_request
    rv = self.handle_user_exception(e)
  File "/Library/Frameworks/Python.framework/Versions/3.7/lib/python3.7/site-packages/flask/app.py", line 1821, in handle_user_exception
    reraise(exc_type, exc_value, tb)
  File "/Library/Frameworks/Python.framework/Versions/3.7/lib/python3.7/site-packages/flask/_compat.py", line 39, in reraise
    raise value
  File "/Library/Frameworks/Python.framework/Versions/3.7/lib/python3.7/site-packages/flask/app.py", line 1950, in full_dispatch_request
    rv = self.dispatch_request()
  File "/Library/Frameworks/Python.framework/Versions/3.7/lib/python3.7/site-packages/flask/app.py", line 1936, in dispatch_request
    return self.view_functions[rule.endpoint](**req.view_args)
  File "/Library/Frameworks/Python.framework/Versions/3.7/lib/python3.7/site-packages/flask_login/utils.py", line 272, in decorated_view
    return func(*args, **kwargs)
  File "/Users/rmj/github/microblog/app/routes.py", line 180, in explore
    page, app.config('POSTS_PER_PAGE'), False)
TypeError: 'Config' object is not callable
2021-01-19 14:21:55,690 ERROR: Exception on /explore [GET] [in /Library/Frameworks/Python.framework/Versions/3.7/lib/python3.7/site-packages/flask/app.py:1892]
Traceback (most recent call last):
  File "/Library/Frameworks/Python.framework/Versions/3.7/lib/python3.7/site-packages/flask/app.py", line 2447, in wsgi_app
    response = self.full_dispatch_request()
  File "/Library/Frameworks/Python.framework/Versions/3.7/lib/python3.7/site-packages/flask/app.py", line 1952, in full_dispatch_request
    rv = self.handle_user_exception(e)
  File "/Library/Frameworks/Python.framework/Versions/3.7/lib/python3.7/site-packages/flask/app.py", line 1821, in handle_user_exception
    reraise(exc_type, exc_value, tb)
  File "/Library/Frameworks/Python.framework/Versions/3.7/lib/python3.7/site-packages/flask/_compat.py", line 39, in reraise
    raise value
  File "/Library/Frameworks/Python.framework/Versions/3.7/lib/python3.7/site-packages/flask/app.py", line 1950, in full_dispatch_request
    rv = self.dispatch_request()
  File "/Library/Frameworks/Python.framework/Versions/3.7/lib/python3.7/site-packages/flask/app.py", line 1936, in dispatch_request
    return self.view_functions[rule.endpoint](**req.view_args)
  File "/Library/Frameworks/Python.framework/Versions/3.7/lib/python3.7/site-packages/flask_login/utils.py", line 272, in decorated_view
    return func(*args, **kwargs)
  File "/Users/rmj/github/microblog/app/routes.py", line 180, in explore
    page, app.config['POSTS_PER_PAGE'], False)
TypeError: 'Config' object is not callable
